Workbook

Sheet Attività
C1: PIANO OPERATIVO · TAPPA ZERO
C2: 14–15 Novembre 2026 · Il Pelagone Hotel & Golf Resort, Gavorrano (GR)
C3: Attività istituzionali e preparazione della Tappa Zero · aggiornato al 29 ottobre 2026
B5: ATTIVITÀ | C5: PRIORITÀ 1 | D5: IN CORSO O IN REVISIONE | E5: DA FARE | G5: FATTE
B6: =COUNTA($C$11:$C$35) -> 20 | C6: =COUNTIFS($E$11:$E$35,1) -> 5 | D6: =COUNTIFS($I$11:$I$35,"In corso")+COUNTIFS($I$11:$I$35,"In revisione") -> 3 | E6: =COUNTIFS($I$11:$I$35,"Da fare") -> 12 | G6: =COUNTIFS($I$11:$I$35,"Fatto") -> 1
B8: LEGENDA | C8: Priorità 1 = urgente, 2 = media, 3 = bassa, vuota = non assegnata. Stato: menu a tendina. Le righe libere in fondo sono pronte per nuove attività.
A10: N. | B10: FILONE | C10: ATTIVITÀ | D10: DETTAGLIO | E10: PRIORITÀ | F10: TEMPI | G10: RESPONSABILI | H10: SCADENZA | I10: STATO | J10: NOTE
A11: 1 | B11: Attività istituzionali | C11: Risoluzione Membership FIFG | D11: Definizione della posizione di AIFG come membro FIFG. | I11: In attesa
A12: 2 | B12: Attività istituzionali | C12: BID Submission Open d'Italia | D12: Candidatura FIFG 500 per l'Open d'Italia, 1–4 luglio a Parco de' Medici. | E12: 1 | H12: 46325 | I12: In revisione | J12: Consegna il 30 ottobre.
A13: 3 | B13: Attività istituzionali | C13: Nuove tessere FIFG | D13: Tessere per i 5 giocatori che vogliono andare a Marrakech (inizio dicembre) e in Turchia (metà dicembre). | I13: Da fare
A14: 4 | B14: Attività istituzionali | C14: Accordo LNF | D14: Accordo con la Lega per il 2027 e definizione del 2028. | I14: Programmata | J14: Riunione già fissata.
A15: 5 | B15: Attività istituzionali | C15: Campi della Nazionale | D15: Definizione dei campi: mancano Tolcinasco, Sutri e San Vigilio. | I15: In corso
A16: 6 | B16: Attività istituzionali | C16: Riunione con tutti gli area manager | D16: Condividere l'accordo LNF e l'organizzazione dello staff della Tappa Zero. | I16: Da fare | J16: Dopo la riunione LNF.
A17: 7 | B17: Attività istituzionali | C17: Area Manager A1–A2 Centro Sud | D17: Aggiornamento e chiarimento del ruolo per le serie A1 e A2. | I17: Programmata | J17: Riunione già fissata.
A18: 8 | B18: Presentazione Tappa Zero | C18: Argomenti e scaletta della presentazione | D18: Temi, ordine degli interventi e tempi della presentazione AIFG. | E18: 1 | F18: 1 settimana | G18: Fabio, Carlo, Alberto | I18: Da fare
A19: 9 | B19: Presentazione Tappa Zero | C19: Nuovo sito internet e Birdie | D19: Presentazione del nuovo sito AIFG e dell'assistente Birdie. | E19: 1 | F19: 1 settimana | G19: Fabio, Carlo | I19: Da fare
A20: 10 | B20: Presentazione Tappa Zero | C20: Vestiario per lo staff | D20: Polo, maglia e pantalone con i loghi; lista taglie degli area manager. | E20: 1 | F20: 1 settimana per la stampa | G20: Fabio, Carlo, Alberto | I20: Da fare | J20: Fabio e Carlo: stampe e lista taglie. Alberto: lista taglie.
A21: 11 | B21: Presentazione Tappa Zero | C21: Grafiche del materiale marketing | D21: Brochure e flyer (cernita dei testi di Fabio), logo Match Zero per le fiches. | E21: 1 | F21: quanto prima | H21: 46329 | I21: Da fare | J21: Ordini Pixartprinting entro martedì 3/11 per la tariffa più bassa.
A22: 12 | B22: Presentazione Tappa Zero | C22: Gestionale, livescoring, regia e classifiche | D22: Presentazione del nuovo gestionale e degli strumenti di gara. | G22: Carlo, Alberto, Stefano Cagnoni | I22: Da fare | J22: Stefano Cagnoni eventualmente di supporto.
A23: 13 | B23: Presentazione Tappa Zero | C23: Timeline operativa delle 2 giornate | D23: Orari, ruoli e passaggi delle due giornate per lo staff operativo. | E23: 2 | F23: mezza giornata | G23: Fabio, Carlo, Alberto | I23: Da fare
A24: 14 | B24: Presentazione Tappa Zero | C24: Discorso introduttivo dello stage della Nazionale | D24: Il messaggio di apertura del ritiro azzurro. | E24: 2 | F24: 2 giorni | G24: Fabio, Carlo, Alberto | I24: Da fare
A25: 15 | B25: Presentazione Tappa Zero | C25: Programma della Nazionale | D25: Programma delle attività della Nazionale durante il weekend. | E25: 2 | F25: 2 giorni | G25: Fabio, Carlo, Alberto | I25: Da fare
A26: 16 | B26: Presentazione Tappa Zero | C26: Controllo e aggiornamento pagamenti | D26: Verifica dei pagamenti ricevuti e da ricevere. | E26: 3 | F26: 1 ora | G26: Fabio, Carlo | I26: Da fare
A27: 17 | B27: Presentazione Tappa Zero | C27: Preventivo della cena | D27: Menu e costo della cena del weekend. | H27: 46327 | I27: Programmata | J27: Da definire domenica con il Direttore.
A28: 18 | B28: Presentazione Tappa Zero | C28: Appartamenti per lo staff | D28: Alloggi per area manager e staff della Nazionale Italiana. | I28: Fatto | J28: Già prenotati: € 1.100 in totale.
A29: 19 | B29: Presentazione Tappa Zero | C29: Community Associazione Italiana FootGolf | D29: Creazione della community ufficiale 2027, con i canali descritti a parte. | I29: Da fare
A30: 20 | B30: Presentazione Tappa Zero | C30: Scorecard | D30: Bozza di Alberto, da rivedere con un eventuale restyling. | G30: Alberto | I30: In corso
A31: 21
A32: 22
A33: 23
A34: 24
A35: 25

Sheet Preventivo
C1: PREVENTIVO DI SPESA · TAPPA ZERO
C2: 14–15 Novembre 2026 · Il Pelagone Hotel & Golf Resort, Gavorrano (GR)
C3: Associazione Italiana FootGolf · materiale, allestimenti, staff e ospitalità · aggiornato al 29 ottobre 2026
B5: TOTALE BASE | D5: OPZIONALI | E5: TOTALE CON OPZIONALI | H5: VOCI DA DEFINIRE | J5: BUDGET DISPONIBILE | M5: RESIDUO SUL TOTALE BASE
B6: =SUMIFS($J$11:$J$44,$M$11:$M$44,"Sì") -> 4588.4 | D6: =SUMIFS($J$11:$J$44,$L$11:$L$44,"Opzionale",$M$11:$M$44,"No") -> 3000 | E6: =B6+D6 -> 7588.4 | H6: =COUNTIFS($L$11:$L$44,"Da definire") -> 7 | M6: =IF(J6="","",J6-B6)
B8: LEGENDA | C8: Celle gialle = da compilare (quantità, prezzi, fornitore, link, foto). Stato e Nel totale: menu a tendina. Il Totale si calcola da Q.tà × Prezzo unitario.
A10: N. | B10: AREA | C10: VOCE | D10: DESCRIZIONE / SPECIFICHE | E10: FORNITORE | F10: TEMPI | G10: Q.TÀ | H10: UNITÀ | I10: PREZZO UNITARIO | J10: TOTALE | K10: IVA | L10: STATO | M10: NEL TOTALE | N10: ORDINE | O10: LINK | P10: FOTO | Q10: NOTE
A11: 1 | B11: A · Materiale marketing | C11: Brochure di presentazione | D11: Formato aperto 63 × 29,7 cm: A4 a 2 pieghe, 6 facciate. | E11: Emmetre Anagni | F11: Stampa 10 giorni | G11: 100 | H11: pz | I11: =180/100 -> 1.8 | J11: =IF(OR(G11="",I11=""),"",G11*I11) -> 180 | K11: Da verificare | L11: Preventivo | M11: Sì | N11: Da ordinare | P11: incolla qui la foto | Q11: Grafica e argomenti da definire.
A12: 2 | B12: A · Materiale marketing | C12: Pieghevole A3 | D12: 2 pieghe, 6 facciate, formato A3 (29 × 42 cm) orizzontale. | E12: Pixartprinting | F12: Ordine entro martedì 3/11 | G12: 250 | H12: pz | I12: =126/250 -> 0.504 | J12: =IF(OR(G12="",I12=""),"",G12*I12) -> 126 | K12: Da verificare | L12: Alternativa | M12: No | N12: Da ordinare | P12: incolla qui la foto | Q12: In alternativa alla brochure. Entro martedì per la tariffa più bassa.
A13: 3 | B13: A · Materiale marketing | C13: Flyer Promozione AIFG 2027 | D13: Flyer con le promozioni della stagione 2027. | E13: Pixartprinting | F13: Ordine entro martedì 3/11 | G13: 250 | H13: pz | I13: =50/250 -> 0.2 | J13: =IF(OR(G13="",I13=""),"",G13*I13) -> 50 | K13: Da verificare | L13: Preventivo | M13: Sì | N13: Da ordinare | P13: incolla qui la foto | Q13: Testi già scritti da Fabio: fare la cernita.
A14: 4 | B14: A · Materiale marketing | C14: Fiches personalizzate | D14: Una fiche per giocatore con il nome, usata in campo come ball marker. Grafica con il logo Match Zero. | E14: Veneto | F14: Stampa 1 settimana | G14: 200 | H14: pz | I14: 1.2 | J14: =IF(OR(G14="",I14=""),"",G14*I14) -> 240 | K14: Da verificare | L14: Preventivo | M14: Sì | N14: Da ordinare | P14: incolla qui la foto | Q14: € 1,20 a fiche, trattabile.
A15: 5 | B15: B · Punto ristoro e briefing | C15: Tavoli pieghevoli | D15: Tavolo pieghevole 180 × 70 × 74 cm, bianco, per briefing e punto ristoro. | E15: Amazon | F15: Consegna 1–2 giorni | G15: 4 | H15: pz | I15: 37 | J15: =IF(OR(G15="",I15=""),"",G15*I15) -> 148 | K15: Da verificare | L15: Preventivo | M15: Sì | N15: Da ordinare | P15: incolla qui la foto
A16: 6 | B16: B · Punto ristoro e briefing | C16: Tovaglie punto ristoro | D16: Tovaglie per i tavoli del punto ristoro. | E16: Amazon | F16: Consegna 1–2 giorni | G16: 4 | H16: pz | I16: 17.85 | J16: =IF(OR(G16="",I16=""),"",G16*I16) -> 71.4 | K16: Da verificare | L16: Preventivo | M16: Sì | N16: Da ordinare | O16: amazon.it/dp/B07CZBPPCB | P16: incolla qui la foto
A17: 7 | B17: B · Punto ristoro e briefing | C17: Bevande, snack e merendine | D17: Rifornimenti per il punto ristoro. | J17: =IF(OR(G17="",I17=""),"",G17*I17) | K17: Da verificare | L17: Da definire | M17: Sì | N17: Da ordinare | P17: incolla qui la foto | Q17: Quantità e spesa da definire.
A18: 8 | B18: B · Punto ristoro e briefing | C18: Sedie per i tavoli briefing | D18: Sedie per i tavoli del briefing. | E18: Amazon | G18: 6 | H18: pz | I18: =130/6 -> 21.666667 | J18: =IF(OR(G18="",I18=""),"",G18*I18) -> 130 | K18: Da verificare | L18: Preventivo | M18: Sì | N18: Da ordinare | O18: amazon.it/dp/B0DMSW62F3 | P18: incolla qui la foto | Q18: € 130 per le 6 sedie.
A19: 9 | B19: C · Percorso e partenze | C19: Radioline per i marshal | D19: Radio per il collegamento fra segreteria, starter e staff sul percorso. | G19: 10 | H19: pz | J19: =IF(OR(G19="",I19=""),"",G19*I19) | K19: Da verificare | L19: Da definire | M19: Sì | N19: Da ordinare | P19: incolla qui la foto | Q19: Se ne occupa Fabio.
A20: 10 | B20: C · Percorso e partenze | C20: Cassa con microfono | D20: Cassa amplificata con microfono per le chiamate alle partenze. | E20: Amazon | G20: 1 | H20: pz | I20: 60 | J20: =IF(OR(G20="",I20=""),"",G20*I20) -> 60 | K20: Da verificare | L20: Preventivo | M20: Sì | N20: Da ordinare | O20: amazon.it/dp/B0CHSD1N1Y | P20: incolla qui la foto
A21: 11 | B21: C · Percorso e partenze | C21: Timer per le partenze | D21: Timer per scandire le partenze. | E21: Amazon | G21: 1 | H21: pz | I21: 60 | J21: =IF(OR(G21="",I21=""),"",G21*I21) -> 60 | K21: Da verificare | L21: Preventivo | M21: Sì | N21: Da ordinare | O21: amazon.it/dp/B0GWH247DF | P21: incolla qui la foto
A22: 12 | B22: C · Percorso e partenze | C22: Bandierine doppio logo, numerate | D22: Bandierine di buca con doppio logo e numero. | E22: golfflags.eu | G22: 1 | H22: fornitura | I22: 390 | J22: =IF(OR(G22="",I22=""),"",G22*I22) -> 390 | K22: Da verificare | L22: Preventivo | M22: Sì | N22: Da ordinare | O22: golfflags.eu | P22: incolla qui la foto | Q22: Verificare quante bandierine comprende la fornitura.
A23: 13 | B23: C · Percorso e partenze | C23: Pannelli presentazione buca | D23: Forex 5 mm personalizzato con supporto in polionda 5 mm, 125 × 45 cm, uno per buca. | E23: Emmetre Anagni | F23: Stampa 10 giorni | G23: 18 | H23: pz | I23: 54 | J23: =IF(OR(G23="",I23=""),"",G23*I23) -> 972 | K23: Esclusa | L23: Preventivo | M23: Sì | N23: Da ordinare | P23: incolla qui la foto
A24: 14 | B24: C · Percorso e partenze | C24: Pannelli buca senza supporto | D24: Pannelli di buca senza supporto in polionda. | E24: Pixartprinting | G24: 18 | H24: pz | I24: =654/18 -> 36.333333 | J24: =IF(OR(G24="",I24=""),"",G24*I24) -> 654 | K24: Da verificare | L24: Alternativa | M24: No | N24: Da ordinare | P24: incolla qui la foto | Q24: Alternativa ai pannelli Emmetre: € 36 l'uno senza supporto.
A25: 15 | B25: C · Percorso e partenze | C25: Partenze Donne e Junior | D25: Cartello di partenza con scritta, 21 × 15 cm con punta, in Bi-Bond. | E25: Emmetre Anagni | G25: 13 | H25: pz | I25: 4 | J25: =IF(OR(G25="",I25=""),"",G25*I25) -> 52 | K25: Esclusa | L25: Preventivo | M25: Sì | N25: Da ordinare | P25: incolla qui la foto | Q25: Nel preventivo il totale indicato è € 54: verificare.
A26: 16 | B26: C · Percorso e partenze | C26: Adesivi per le partenze | D26: Adesivi per le nuove partenze con nuova grafica, logo e par. | E26: Pixartprinting | H26: pz | J26: =IF(OR(G26="",I26=""),"",G26*I26) | K26: Da verificare | L26: Da definire | M26: Sì | N26: Da ordinare | P26: incolla qui la foto | Q26: Prezzo da verificare su Pixartprinting.
A27: 17 | B27: C · Percorso e partenze | C27: Mini vele di partenza | D27: Una per buca, stile Open internazionale, antivento. Formato 67 × 200 o 85 × 130 cm. | E27: Pixartprinting | G27: 18 | H27: pz | I27: 125 | J27: =IF(OR(G27="",I27=""),"",G27*I27) -> 2250 | K27: Da verificare | L27: Opzionale | M27: No | N27: Da ordinare | P27: incolla qui la foto | Q27: Stesso prezzo per i due formati: € 125 l'una.
A28: 18 | B28: C · Percorso e partenze | C28: Cubi per buca 1 e buca 18 | D28: Cubi in polionda 5 mm, 30 × 30 cm, stile Open d'Italia. | G28: 1 | H28: fornitura | I28: =150/1 -> 150 | J28: =IF(OR(G28="",I28=""),"",G28*I28) -> 150 | K28: Da verificare | L28: Opzionale | M28: No | N28: Da ordinare | P28: incolla qui la foto | Q28: Prezzo del preventivo precedente.
A29: 19 | B29: D · Immagine e media | C29: Wall istituzionale per foto | D29: Banner con asola 210 × 160/170 cm per le foto dei giocatori. | E29: Emmetre Anagni | G29: 1 | H29: pz | I29: 85 | J29: =IF(OR(G29="",I29=""),"",G29*I29) -> 85 | K29: Esclusa | L29: Preventivo | M29: Sì | N29: Da ordinare | P29: incolla qui la foto
A30: 20 | B30: D · Immagine e media | C30: Telo per videoproiettore | D30: Telo da 120 pollici per la presentazione AIFG. | E30: Amazon | G30: 1 | H30: pz | I30: 80 | J30: =IF(OR(G30="",I30=""),"",G30*I30) -> 80 | K30: Da verificare | L30: Preventivo | M30: Sì | N30: Da ordinare | P30: incolla qui la foto
A31: 21 | B31: D · Immagine e media | C31: Drone per riprese e diretta | D31: Riprese aeree e diretta live della tappa. | G31: 1 | H31: pz | I31: 600 | J31: =IF(OR(G31="",I31=""),"",G31*I31) -> 600 | K31: Da verificare | L31: Opzionale | M31: No | N31: Da ordinare | P31: incolla qui la foto | Q31: Domenica si prova il drone di Alberto. Preventivo € 400–600: messo il massimo.
A32: 22 | B32: D · Immagine e media | C32: Fotografo | D32: Servizio fotografico del weekend. | G32: 2 | H32: giornate | I32: 150 | J32: =IF(OR(G32="",I32=""),"",G32*I32) -> 300 | K32: Da verificare | L32: Stima | M32: Sì | N32: Da ordinare | P32: incolla qui la foto | Q32: Da trovare. Base € 80–150 a giornata: messo il massimo per 2 giornate.
A33: 23 | B33: D · Immagine e media | C33: Tovaglia tavolo istituzionale | D33: Tovaglia per il tavolo della presentazione istituzionale. | G33: 1 | H33: pz | J33: =IF(OR(G33="",I33=""),"",G33*I33) | K33: Da verificare | L33: Da definire | M33: Sì | N33: Da ordinare | P33: incolla qui la foto | Q33: Da verificare.
A34: 24 | B34: E · Accoglienza | C34: Tovaglie neutre per l'accoglienza | D34: Tovaglie neutre per i tavoli dell'accoglienza. | E34: Amazon | H34: pz | J34: =IF(OR(G34="",I34=""),"",G34*I34) | K34: Da verificare | L34: Da definire | M34: Sì | N34: Da ordinare | P34: incolla qui la foto | Q34: Da verificare su Amazon.
A35: 25 | B35: E · Accoglienza | C35: Badge con collarini per invitati | D35: Collarini con doppio moschettone, personalizzati. | E35: Emmetre Anagni | G35: 100 | H35: pz | I35: =370/100 -> 3.7 | J35: =IF(OR(G35="",I35=""),"",G35*I35) -> 370 | K35: Esclusa | L35: Preventivo | M35: Sì | N35: Da ordinare | P35: incolla qui la foto | Q35: In alternativa: collarini e badge su Amazon e solo le stampe.
A36: 26 | B36: E · Accoglienza | C36: Ragazze immagine | D36: Servizio di ragazze immagine per l'accoglienza e le premiazioni. | E36: Daniele Busoni | G36: 1 | H36: servizio | I36: 300 | J36: =IF(OR(G36="",I36=""),"",G36*I36) -> 300 | K36: Da verificare | L36: Preventivo | M36: Sì | N36: Da ordinare | P36: incolla qui la foto
A37: 27 | B37: F · Staff e ospitalità | C37: Vestiario staff | D37: Polo, maglia e pantalone per lo staff della tappa, con i loghi. | F37: 1 settimana per la stampa | H37: kit | J37: =IF(OR(G37="",I37=""),"",G37*I37) | K37: Da verificare | L37: Da definire | M37: Sì | N37: Da ordinare | P37: incolla qui la foto | Q37: Quantità dalla lista taglie degli area manager.
A38: 28 | B38: F · Staff e ospitalità | C38: Appartamenti per lo staff | D38: Alloggi per area manager e staff della Nazionale Italiana. | G38: 1 | H38: soggiorno | I38: =1100/1 -> 1100 | J38: =IF(OR(G38="",I38=""),"",G38*I38) -> 1100 | K38: Da verificare | L38: Confermato | M38: Sì | N38: Da ordinare | P38: incolla qui la foto | Q38: Già prenotati.
A39: 29 | B39: F · Staff e ospitalità | C39: Cena | D39: Cena del weekend. | H39: coperti | J39: =IF(OR(G39="",I39=""),"",G39*I39) | K39: Da verificare | L39: Da definire | M39: Sì | N39: Da ordinare | P39: incolla qui la foto | Q39: Preventivo da definire domenica con il Direttore.
A40: 30 | J40: =IF(OR(G40="",I40=""),"",G40*I40) | P40: incolla qui la foto
A41: 31 | J41: =IF(OR(G41="",I41=""),"",G41*I41) | P41: incolla qui la foto
A42: 32 | J42: =IF(OR(G42="",I42=""),"",G42*I42) | P42: incolla qui la foto
A43: 33 | J43: =IF(OR(G43="",I43=""),"",G43*I43) | P43: incolla qui la foto
...

Sheet Riepilogo per area
B1: RIEPILOGO PER AREA
B2: Tappa Zero · 14–15 Novembre 2026
B4: AREA | C4: N. VOCI | D4: TOTALE BASE | E4: OPZIONALI | F4: TOTALE | G4: % BASE
A5: A | B5: Materiale marketing | C5: =COUNTIFS(Preventivo!$B$11:$B$44,"A · Materiale marketing") -> 4 | D5: =SUMIFS(Preventivo!$J$11:$J$44,Preventivo!$B$11:$B$44,"A · Materiale marketing",Preventivo!$M$11:$M$44,"Sì") -> 470 | E5: =SUMIFS(Preventivo!$J$11:$J$44,Preventivo!$B$11:$B$44,"A · Materiale marketing",Preventivo!$L$11:$L$44,"Opzionale",Preventivo!$M$11:$M$44,"No") -> 0 | F5: =D5+E5 -> 470 | G5: =IF($D$11=0,0,D5/$D$11) -> 0.10243222
A6: B | B6: Punto ristoro e briefing | C6: =COUNTIFS(Preventivo!$B$11:$B$44,"B · Punto ristoro e briefing") -> 4 | D6: =SUMIFS(Preventivo!$J$11:$J$44,Preventivo!$B$11:$B$44,"B · Punto ristoro e briefing",Preventivo!$M$11:$M$44,"Sì") -> 349.4 | E6: =SUMIFS(Preventivo!$J$11:$J$44,Preventivo!$B$11:$B$44,"B · Punto ristoro e briefing",Preventivo!$L$11:$L$44,"Opzionale",Preventivo!$M$11:$M$44,"No") -> 0 | F6: =D6+E6 -> 349.4 | G6: =IF($D$11=0,0,D6/$D$11) -> 0.076148549
A7: C | B7: Percorso e partenze | C7: =COUNTIFS(Preventivo!$B$11:$B$44,"C · Percorso e partenze") -> 10 | D7: =SUMIFS(Preventivo!$J$11:$J$44,Preventivo!$B$11:$B$44,"C · Percorso e partenze",Preventivo!$M$11:$M$44,"Sì") -> 1534 | E7: =SUMIFS(Preventivo!$J$11:$J$44,Preventivo!$B$11:$B$44,"C · Percorso e partenze",Preventivo!$L$11:$L$44,"Opzionale",Preventivo!$M$11:$M$44,"No") -> 2400 | F7: =D7+E7 -> 3934 | G7: =IF($D$11=0,0,D7/$D$11) -> 0.33432133
A8: D | B8: Immagine e media | C8: =COUNTIFS(Preventivo!$B$11:$B$44,"D · Immagine e media") -> 5 | D8: =SUMIFS(Preventivo!$J$11:$J$44,Preventivo!$B$11:$B$44,"D · Immagine e media",Preventivo!$M$11:$M$44,"Sì") -> 465 | E8: =SUMIFS(Preventivo!$J$11:$J$44,Preventivo!$B$11:$B$44,"D · Immagine e media",Preventivo!$L$11:$L$44,"Opzionale",Preventivo!$M$11:$M$44,"No") -> 600 | F8: =D8+E8 -> 1065 | G8: =IF($D$11=0,0,D8/$D$11) -> 0.10134252
A9: E | B9: Accoglienza | C9: =COUNTIFS(Preventivo!$B$11:$B$44,"E · Accoglienza") -> 3 | D9: =SUMIFS(Preventivo!$J$11:$J$44,Preventivo!$B$11:$B$44,"E · Accoglienza",Preventivo!$M$11:$M$44,"Sì") -> 670 | E9: =SUMIFS(Preventivo!$J$11:$J$44,Preventivo!$B$11:$B$44,"E · Accoglienza",Preventivo!$L$11:$L$44,"Opzionale",Preventivo!$M$11:$M$44,"No") -> 0 | F9: =D9+E9 -> 670 | G9: =IF($D$11=0,0,D9/$D$11) -> 0.1460204
A10: F | B10: Staff e ospitalità | C10: =COUNTIFS(Preventivo!$B$11:$B$44,"F · Staff e ospitalità") -> 3 | D10: =SUMIFS(Preventivo!$J$11:$J$44,Preventivo!$B$11:$B$44,"F · Staff e ospitalità",Preventivo!$M$11:$M$44,"Sì") -> 1100 | E10: =SUMIFS(Preventivo!$J$11:$J$44,Preventivo!$B$11:$B$44,"F · Staff e ospitalità",Preventivo!$L$11:$L$44,"Opzionale",Preventivo!$M$11:$M$44,"No") -> 0 | F10: =D10+E10 -> 1100 | G10: =IF($D$11=0,0,D10/$D$11) -> 0.23973498
B11: TOTALE | C11: =SUM(C5:C10) -> 29 | D11: =SUM(D5:D10) -> 4588.4 | E11: =SUM(E5:E10) -> 3000 | F11: =SUM(F5:F10) -> 7588.4 | G11: =IF($D$11=0,0,SUM(G5:G10)) -> 1

Sheet Community
B1: AIFG | COMMUNITY UFFICIALE 2027
B2: Struttura dei canali della community ufficiale
B4: CANALE | C4: SEZIONE | D4: REFERENTE / NOTE
B5: 📢 Comunicazioni ufficiali
B6: 🏛️ Direzione
B7: 🗺️ Area manager
C8: ├─ Centro Sud
C9: ├─ Centro
C10: ├─ Nord
C11: └─ Nord Est
B12: 🏆 Campionati
C13: ├─ Serie A
C14: ├─ Serie A1
C15: └─ Serie A2
B16: 🧠 Comitato tecnico
B17: 🇮🇹 Nazionale
C18: ├─ Men
C19: ├─ Women
C20: ├─ Senior
C21: ├─ Senior Plus
C22: └─ Junior
B23: 🏌️ Organizzatori
B24: 💻 Staff & operativo
B25: 📝 Iscrizioni
